<?xml version="1.0" encoding="utf-8"?>
<!-- =================================================================================== -->
<!-- |    This document was autogenerated by xacro from elfin5.urdf.xacro              | -->
<!-- |    EDITING THIS FILE BY HAND IS NOT RECOMMENDED                                 | -->
<!-- =================================================================================== -->
<robot name="elfin5">
  <material name="black">
    <color rgba="0.0 0.0 0.0 1.0"/>
  </material>
  <material name="blue">
    <color rgba="0.0 0.0 0.8 1.0"/>
  </material>
  <material name="green">
    <color rgba="0.0 0.8 0.0 1.0"/>
  </material>
  <material name="grey">
    <color rgba="0.2 0.2 0.2 1.0"/>
  </material>
  <material name="orange">
    <color rgba="1.0 0.423529411765 0.0392156862745 1.0"/>
  </material>
  <material name="brown">
    <color rgba="0.870588235294 0.811764705882 0.764705882353 1.0"/>
  </material>
  <material name="red">
    <color rgba="0.8 0.0 0.0 1.0"/>
  </material>
  <material name="white">
    <color rgba="1.0 1.0 1.0 1.0"/>
  </material>
  <material name="metal">
    <color rgba="0.768627450980392 0.749019607843137 0.729411764705882 1"/>
  </material>
  <material name="metal_grey">
    <color rgba="0.501960784313725 0.501960784313725 0.501960784313725 1"/>
  </material>
  <material name="metal_white">
    <color rgba="0.866666666666667 0.866666666666667 0.890196078431373 1"/>
  </material>
  <!-- ros_control plugin -->
  <gazebo>
    <plugin filename="libgazebo_ros_control.so" name="gazebo_ros_control">
      <robotSimType>gazebo_ros_control/DefaultRobotHWSim</robotSimType>
      <legacyModeNS>true</legacyModeNS>
    </plugin>
  </gazebo>
  <gazebo reference="elfin_link2">
    <visual name="visual">
      <material>
        <script>
          <uri>file://media/materials/scripts/gazebo.material</uri>
          <name>Gazebo/Grey</name>
        </script>
      </material>
    </visual>
  </gazebo>
  <gazebo reference="elfin_link4">
    <visual name="visual">
      <material>
        <script>
          <uri>file://media/materials/scripts/gazebo.material</uri>
          <name>Gazebo/Grey</name>
        </script>
      </material>
    </visual>
  </gazebo>
  <transmission name="elfin_joint1_trans">
    <type>transmission_interface/SimpleTransmission</type>
    <joint name="elfin_joint1">
      <hardwareInterface>hardware_interface/PositionJointInterface</hardwareInterface>
    </joint>
    <actuator name="elfin_joint1_motor">
      <mechanicalReduction>1</mechanicalReduction>
    </actuator>
  </transmission>
  <transmission name="elfin_joint2_trans">
    <type>transmission_interface/SimpleTransmission</type>
    <joint name="elfin_joint2">
      <hardwareInterface>hardware_interface/PositionJointInterface</hardwareInterface>
    </joint>
    <actuator name="elfin_joint2_motor">
      <mechanicalReduction>1</mechanicalReduction>
    </actuator>
  </transmission>
  <transmission name="elfin_joint3_trans">
    <type>transmission_interface/SimpleTransmission</type>
    <joint name="elfin_joint3">
      <hardwareInterface>hardware_interface/PositionJointInterface</hardwareInterface>
    </joint>
    <actuator name="elfin_joint3_motor">
      <mechanicalReduction>1</mechanicalReduction>
    </actuator>
  </transmission>
  <transmission name="elfin_joint4_trans">
    <type>transmission_interface/SimpleTransmission</type>
    <joint name="elfin_joint4">
      <hardwareInterface>hardware_interface/PositionJointInterface</hardwareInterface>
    </joint>
    <actuator name="elfin_joint4_motor">
      <mechanicalReduction>1</mechanicalReduction>
    </actuator>
  </transmission>
  <transmission name="elfin_joint5_trans">
    <type>transmission_interface/SimpleTransmission</type>
    <joint name="elfin_joint5">
      <hardwareInterface>hardware_interface/PositionJointInterface</hardwareInterface>
    </joint>
    <actuator name="elfin_joint5_motor">
      <mechanicalReduction>1</mechanicalReduction>
    </actuator>
  </transmission>
  <transmission name="elfin_joint6_trans">
    <type>transmission_interface/SimpleTransmission</type>
    <joint name="elfin_joint6">
      <hardwareInterface>hardware_interface/PositionJointInterface</hardwareInterface>
    </joint>
    <actuator name="elfin_joint6_motor">
      <mechanicalReduction>1</mechanicalReduction>
    </actuator>
  </transmission>
  <link name="world"/>
  <joint name="world_base" type="fixed">
    <origin rpy="0 0 0" xyz="0 0 0"/>
    <parent link="world"/>
    <child link="elfin_base_link"/>
  </joint>
  <link name="elfin_base_link"/>
  <joint name="elfin_base_joint" type="fixed">
    <origin rpy="0 0 1.57079632679" xyz="0 0 0"/>
    <parent link="elfin_base_link"/>
    <child link="elfin_base"/>
  </joint>
  <link name="elfin_base">
    <inertial>
      <origin rpy="0 0 0" xyz="0.000209 0.001319 0.025619"/>
      <mass value="2.13370989"/>
      <inertia ixx="0.0040358799" ixy="0.000175512" ixz="5.8401e-06" iyy="0.0041550303" iyz="3.38355e-05" izz="0.0070803951"/>
    </inertial>
    <visual>
      <origin rpy="0 0 0" xyz="0 0 0"/>
      <geometry>
        <mesh filename="package://elfin_description/meshes/elfin5/elfin_base.STL"/>
      </geometry>
      <material name="metal_white"/>
    </visual>
    <collision>
      <origin rpy="0 0 0" xyz="0 0 0"/>
      <geometry>
        <mesh filename="package://elfin_description/meshes/elfin5/elfin_base.STL"/>
      </geometry>
    </collision>
  </link>
  <link name="elfin_link1">
    <inertial>
      <origin rpy="0 0 0" xyz="-0.0217491 0.1389011 0.0000125"/>
      <mass value="7.96222548"/>
      <inertia ixx="0.0401380494" ixy="0.0088981494" ixz="-3.09e-06" iyy="0.0222824535" iyz="-1.6068e-06" izz="0.0473608317"/>
    </inertial>
    <visual>
      <origin rpy="0 0 0" xyz="0 0 0"/>
      <geometry>
        <mesh filename="package://elfin_description/meshes/elfin5/elfin_link1.STL"/>
      </geometry>
      <material name="metal"/>
    </visual>
    <collision>
      <origin rpy="0 0 0" xyz="0 0 0"/>
      <geometry>
        <mesh filename="package://elfin_description/meshes/elfin5/elfin_link1.STL"/>
      </geometry>
    </collision>
  </link>
  <joint name="elfin_joint1" type="revolute">
    <origin rpy="1.57079632679 0 0" xyz="0 0 0.03"/>
    <parent link="elfin_base"/>
    <child link="elfin_link1"/>
    <axis xyz="0 1 0"/>
    <limit effort="200" lower="-3.14" upper="3.14" velocity="1.57"/>
  </joint>
  <link name="elfin_link2">
    <inertial>
      <origin rpy="0 0 0" xyz="-0.0522485 0.1580101 -0.0000003"/>
      <mass value="3.73459563"/>
      <inertia ixx="0.091957473" ixy="-0.0039070269" ixz="-7.416e-07" iyy="0.0051960204" iyz="-6.489e-06" izz="0.0909910446"/>
    </inertial>
    <visual>
      <origin rpy="0 0 0" xyz="0 0 0"/>
      <geometry>
        <mesh filename="package://elfin_description/meshes/elfin5/elfin_link2.STL"/>
      </geometry>
      <material name="metal_grey"/>
    </visual>
    <collision>
      <origin rpy="0 0 0" xyz="0 0 0"/>
      <geometry>
        <mesh filename="package://elfin_description/meshes/elfin5/elfin_link2.STL"/>
      </geometry>
    </collision>
  </link>
  <joint name="elfin_joint2" type="revolute">
    <origin rpy="0 0 0" xyz="-0.078069 0.19 0"/>
    <parent link="elfin_link1"/>
    <child link="elfin_link2"/>
    <axis xyz="-1 0 0"/>
    <limit effort="200" lower="-2.35" upper="2.35" velocity="1.57"/>
  </joint>
  <link name="elfin_link3">
    <inertial>
      <origin rpy="0 0 0" xyz="0.0587091 -0.0414608 -0.0000210"/>
      <mass value="4.71497847"/>
      <inertia ixx="0.0163101015" ixy="0.003836235" ixz="-5.562e-07" iyy="0.0098219049" iyz="-2.0703e-06" izz="0.0201630843"/>
    </inertial>
    <visual>
      <origin rpy="0 0 0" xyz="0 0 0"/>
      <geometry>
        <mesh filename="package://elfin_description/meshes/elfin5/elfin_link3.STL"/>
      </geometry>
      <material name="metal"/>
    </visual>
    <collision>
      <origin rpy="0 0 0" xyz="0 0 0"/>
      <geometry>
        <mesh filename="package://elfin_description/meshes/elfin5/elfin_link3.STL"/>
      </geometry>
    </collision>
  </link>
  <joint name="elfin_joint3" type="revolute">
    <origin rpy="3.14159265359 0 0" xyz="0 0.38 0"/>
    <parent link="elfin_link2"/>
    <child link="elfin_link3"/>
    <axis xyz="1 0 0"/>
    <limit effort="104" lower="-2.61" upper="2.61" velocity="1.57"/>
  </joint>
  <link name="elfin_link4">
    <inertial>
      <origin rpy="0 0 0" xyz="-0.0587964 0.1436154 -0.0000478"/>
      <mass value="1.46783034"/>
      <inertia ixx="0.0167614269" ixy="0.0047923428" ixz="-1.6377e-06" iyy="0.004072002" iyz="6.0255e-06" izz="0.0187714101"/>
    </inertial>
    <visual>
      <origin rpy="0 0 0" xyz="0 0 0"/>
      <geometry>
        <mesh filename="package://elfin_description/meshes/elfin5/elfin_link4.STL"/>
      </geometry>
      <material name="metal_grey"/>
    </visual>
    <collision>
      <origin rpy="0 0 0" xyz="0 0 0"/>
      <geometry>
        <mesh filename="package://elfin_description/meshes/elfin5/elfin_link4.STL"/>
      </geometry>
    </collision>
  </link>
  <joint name="elfin_joint4" type="revolute">
    <origin rpy="-3.14159265359 0 0" xyz="0.078069 -0.11342 0"/>
    <parent link="elfin_link3"/>
    <child link="elfin_link4"/>
    <axis xyz="0 1 0"/>
    <limit effort="104" lower="-3.14" upper="3.14" velocity="1.57"/>
  </joint>
  <link name="elfin_link5">
    <inertial>
      <origin rpy="0 0 0" xyz="-0.0159154 -0.0365660 0.0000004"/>
      <mass value="2.49795291"/>
      <inertia ixx="0.0060069291" ixy="0.0014650926" ixz="3.09e-08" iyy="0.0034992705" iyz="-3.708e-07" izz="0.0076218249"/>
    </inertial>
    <visual>
      <origin rpy="0 0 0" xyz="0 0 0"/>
      <geometry>
        <mesh filename="package://elfin_description/meshes/elfin5/elfin_link5.STL"/>
      </geometry>
      <material name="metal"/>
    </visual>
    <collision>
      <origin rpy="0 0 0" xyz="0 0 0"/>
      <geometry>
        <mesh filename="package://elfin_description/meshes/elfin5/elfin_link5.STL"/>
      </geometry>
    </collision>
  </link>
  <joint name="elfin_joint5" type="revolute">
    <origin rpy="-3.14159265359 0 0" xyz="0 0.30658 0"/>
    <parent link="elfin_link4"/>
    <child link="elfin_link5"/>
    <axis xyz="1 0 0"/>
    <limit effort="34" lower="-2.56" upper="2.56" velocity="1.57"/>
  </joint>
  <link name="elfin_link6">
    <inertial>
      <origin rpy="0 0 0" xyz="-0.0009237 -0.042691 -0.0003367"/>
      <mass value="0.45519408"/>
      <inertia ixx="0.0005996763" ixy="4.326e-06" ixz="-8.9301e-06" iyy="0.0006053928" iyz="1.545e-07" izz="0.0006024264"/>
    </inertial>
    <visual>
      <origin rpy="0 0 0" xyz="0 0 0"/>
      <geometry>
        <mesh filename="package://elfin_description/meshes/elfin5/elfin_link6.STL"/>
      </geometry>
      <material name="metal_white"/>
    </visual>
    <collision>
      <origin rpy="0 0 0" xyz="0 0 0"/>
      <geometry>
        <mesh filename="package://elfin_description/meshes/elfin5/elfin_link6.STL"/>
      </geometry>
    </collision>
  </link>
  <joint name="elfin_joint6" type="revolute">
    <origin rpy="0 0 0" xyz="0 -0.1065 0"/>
    <parent link="elfin_link5"/>
    <child link="elfin_link6"/>
    <axis xyz="0 -1 0"/>
    <limit effort="34" lower="-3.14" upper="3.14" velocity="1.57"/>
  </joint>
  <link name="elfin_end_link"/>
  <joint name="elfin_end_joint" type="fixed">
    <origin rpy="1.57079632679 1.57079632679 0" xyz="0 -0.0735 0"/>
    <parent link="elfin_link6"/>
    <child link="elfin_end_link"/>
  </joint>
  <link name="elfin_dummy_gripper"/>
  <joint name="elfin_dummy_joint" type="fixed">
    <origin rpy="1.57079632679 1.57079632679 0" xyz="0 -0.0935 0"/>
    <parent link="elfin_link6"/>
    <child link="elfin_dummy_gripper"/>
  </joint>
</robot>
